Workbook

Sheet 00-Lisez-moi
B2: Sentier — Source unique v3.0
B3: 3 septembre 2026. Features + arborescence des leçons + stratégie de validation. Remplace les trois fichiers séparés.
B5: Comment lire
B6: 01-Hors-périmètre — ce qu'on ne construit pas, pour que personne n'ouvre F-V2 par erreur.
B7: 10-Features — tickets produit (app + production). IDs F-xxx.
B8: 11-Suivi-features — formules.
B9: 12-Sprint-0 — ordre de code pour la première écoute.
B10: 20-Domaines / 21-Sous-domaines / 22-Leçons — taxonomie complète + champs de contrat.
B11: 23-Fiches-pilote — les 12 contrats exécutables de l'arbre Parc.
B12: 24-Arbre-Parc — ordre des scènes.
B13: 30-Strategie-validation — pipeline, gravités, preuves, ontologie.
B14: 31-Backlog-validation — tickets VAL-xxx (service de prod, pas l'app).
... B21: Le générateur cherche une histoire. Les validateurs cherchent les défauts. La publication ne croit personne.

Sheet 01-Hors-périmètre
B2: Hors périmètre — ne pas ticketiser
A4: # | B4: Interdit / reporté
A5: 1 | B5: Conversation vocale ouverte avec l'enfant (MVP).
A6: 2 | B6: Génération de texte ou d'audio sur le téléphone pendant la session.
A7: 3 | B7: Prénom de l'enfant dit à voix haute comme variable libre.
A8: 4 | B8: Illustrations, vidéo ou mini-jeu visuel nécessaires à la compréhension.
A9: 5 | B9: Réseau social, contenus publics créés par les familles.
A10: 6 | B10: Diagnostic, bulletin, note, évaluation scolaire certifiée.
A11: 7 | B11: Religion, politique, guerre, crime, tuerie dans l'audio enfant.
A12: 8 | B12: Discours de genre, deux papas, deux mamans — y compris « pour expliquer que non ».
A13: 9 | B13: Description opératoire d'un geste dangereux, même pour l'interdire.
A14: 10 | B14: Obéissance aveugle à n'importe quel adulte.
A15: 11 | B15: Publicité ciblant l'enfant, récompense pour écouter trop longtemps.
A16: 12 | B16: Mini-LLM et voice-to-voice (F-V2-*) : Phase 6–7 seulement, après corpus neutre.
A17: 13 | B17: Leçon parentale publiée sans isolation ni validateurs (F-CUS est P2).

Sheet 11-Suivi-features
B2: Suivi features
B4: Total | C4: =COUNTA('10-Features'!A2:A68) -> 67
B5: P0 | C5: =COUNTIF('10-Features'!E:E,"P0") -> 31
B6: P1 | C6: =COUNTIF('10-Features'!E:E,"P1") -> 24
B7: P2 | C7: =COUNTIF('10-Features'!E:E,"P2") -> 9
B8: P3 | C8: =COUNTIF('10-Features'!E:E,"P3") -> 3
B10: À faire | C10: =COUNTIF('10-Features'!I:I,"À faire") -> 67
B11: En cours | C11: =COUNTIF('10-Features'!I:I,"En cours") -> 0
B12: Fait | C12: =COUNTIF('10-Features'!I:I,"Fait") -> 0
B13: % fait | C13: =IF(C4=0,0,C12/C4) -> 0

Sheet 11b-Suivi-validation
B2: Suivi validation
B4: Total | C4: =COUNTA('31-Backlog-validation'!A2:A37) -> 36
B5: P0 | C5: =COUNTIF('31-Backlog-validation'!E:E,"P0") -> 20
B6: P1 | C6: =COUNTIF('31-Backlog-validation'!E:E,"P1") -> 14
B7: À faire | C7: =COUNTIF('31-Backlog-validation'!G:G,"À faire") -> 36
B8: Fait | C8: =COUNTIF('31-Backlog-validation'!G:G,"Fait") -> 0
B9: % fait | C9: =IF(C4=0,0,C8/C4) -> 0

Sheet 12-Sprint-0
B2: Sprint 0 — première écoute hors ligne, sans LLM
A4: Ordre | B4: ID | C4: Titre | D4: Pourquoi
A5: 1 | B5: F-SCH-001 | C5: Schémas JSON | D5: Sinon chaque PR invente un format.
A6: 2 | B6: F-TAX-001 | C6: Taxonomie | D6: Les IDs de leçons.
A7: 3 | B7: F-TAX-002 | C7: Fiche leçon | D7: Contrat du parc.
A8: 4 | B8: F-NEU-001 | C8: Hors jardin | D8: Avant d'écrire une phrase.
A9: 5 | B9: F-NEU-002 | C9: Formulation positive | D9: Idem.
A10: 6 | B10: F-NAR-001 | C10: Modèle arbre | D10: Graphe.
A11: 7 | B11: VAL-PED-001 | C11: Contrat obligatoire | D11: Porte d'entrée validation.
A12: 8 | B12: VAL-GRAPH-001 | C12: Compilateur | D12: Structure.
A13: 9 | B13: VAL-GRAPH-002 | C13: Couverture 100 % | D13: Tous les chemins.
A14: 10 | B14: VAL-NEU-010 | C14: Filtre hors jardin | D14: Déterministe.
A15: 11 | B15: VAL-SAFE-002 | C15: Imitabilité | D15: Déterministe.
... A42: 38 | B42: F-PRI-001 | C42: Privacy | D42: Avant store.

Sheet 10-Features
A1: ID | B1: Epic | C1: Titre | D1: Description | E1: Priorité | F1: Phase | G1: Dépendances | H1: Branche Git | I1: Statut
A2: F-TAX-001 | B2: Référentiel | C2: Taxonomie 3 niveaux | D2: Domaine → sous-domaine → leçon. IDs immuables (SEC.RUE.002). Voir onglet Leçons. | E2: P0 | F2: P0-Cadrage | G2: — | H2: feat/F-TAX-001-taxonomie | I2: À faire
A3: F-TAX-002 | B3: Référentiel | C3: Fiche leçon versionnée | D3: Champs : lesson_id, version, âge, objectif, required_messages, safe_actions, misconceptions, forbidden_messages, answer_intents, framing, sensitivity, positive_scripts, banned_child_audio. Une modif de message obligatoire = nouvelle version. | E3: P0 | F3: P0-Cadrage | G3: F-TAX-001 | H3: feat/F-TAX-002-fiche-lecon | I3: À faire
A4: F-TAX-003 | B4: Référentiel | C4: Priorités / exclusions parent | D4: Activer un domaine, cocher des leçons, top priorités, plus tard, exclure. Score : priorité + compatibilité + révision − répétition − transition absurde − dépassement durée. | E4: P0 | F4: P2-App | G4: F-TAX-001;F-PRF-001 | H4: feat/F-TAX-003-priorites-parent | I4: À faire
A5: F-TAX-004 | B5: Référentiel | C5: Couverture et versions de leçons | D5: Vue : jamais rencontrée / trop répétée. Anciens arbres restent jouables, plus renouvelés si la fiche a changé. | E5: P2 | F5: P4-Stock | G5: F-TAX-002 | H5: feat/F-TAX-004-couverture | I5: À faire
A6: F-SCH-001 | B6: Référentiel | C6: Schémas JSON versionnés | D6: Contrats : lesson, tree, node, intent, validation_report, package_manifest. Enums d'états uniques. Breaking change = bump de version majeur. Voir onglet Contrats. | E6: P0 | F6: P0-Cadrage | G6: F-TAX-002;F-NAR-001 | H6: feat/F-SCH-001-schemas | I6: À faire
A7: F-NEU-001 | B7: Éditorial | C7: Vocabulaire hors jardin absent de l'audio | D7: Audio enfant : quotidien (maison, école, parc, papa, maman, frère, sœur). Interdit : religion, politique, guerre, crime, tuerie, discours de genre, deux papas / deux mamans. On n'explique pas pour rejeter : c'est absent. Listes en métadonnées internes. | E7: P0 | F7: P0-Cadrage | G7: F-TAX-002 | H7: feat/F-NEU-001-hors-jardin | I7: À faire
A8: F-NEU-002 | B8: Éditorial | C8: Formulation positive des dangers | D8: Dire quoi faire. Ne pas nommer le geste dangereux. Pas de choix qui décrit un geste imitable. Correction = conduite sûre seulement. | E8: P0 | F8: P0-Cadrage | G8: F-TAX-002 | H8: feat/F-NEU-002-positif | I8: À faire
A9: F-NEU-003 | B9: Éditorial | C9: Lexique des émotions | D9: Nom + cause + indice du corps + geste sûr. L'émotion n'est pas une faute. | E9: P1 | F9: P1-Contenu | G9: F-TAX-002 | H9: feat/F-NEU-003-emotions | I9: À faire
A10: F-NEU-004 | B10: Éditorial | C10: Différences et moqueries | D10: Taille, poids, lunettes, timidité, énergie, besoin de temps. Inviter ≠ forcer. Geste / objet / regard. Ne pas finir les phrases. Photo non consentie interdite. Trois rôles : visé, témoin, auteur. | E10: P1 | F10: P1-Contenu | G10: F-TAX-002 | H10: feat/F-NEU-004-differences | I10: À faire
A11: F-NEU-005 | B11: Éditorial | C11: Validateur éditorial bloquant | D11: Hors-jardin, étiquettes, menaces affectives, « ne + geste dangereux », héros modèle risqué, famille hors papa-maman-enfants. Un hit refuse l'arbre. | E11: P0 | F11: P1-Contenu | G11: F-NEU-001;F-NEU-002;VAL-PIPE | H11: feat/F-NEU-005-validateur-editorial | I11: À faire
A12: F-NAR-001 | B12: Moteur | C12: Modèle arbre / nœud / branche | D12: Types : audio, question_comprehension, question_lesson, choice_story, feedback, transition, silence_check, ending. Fins indépendantes. Tous les chemins aboutissent. Pas de boucle. | E12: P0 | F12: P0-Cadrage | G12: F-TAX-002;F-SCH-001 | H12: feat/F-NAR-001-modele-arbre | I12: À faire
... A68: F-V2-003 | B68: V2 | C68: Voice-to-voice | D68: Dernière étape volontaire. Pas un argument de vente MVP. | E68: P3 | F68: P7-V2 | G68: F-V2-002 | H68: feat/F-V2-003-v2v | I68: À faire

Sheet 20-Domaines
A1: ID | B1: Domaine | C1: Intention | D1: Sous-domaines | E1: Nb leçons | F1: Nb pilote | G1: Décors
A2: SAN | B2: Santé et quotidien | C2: Prendre soin de son corps. | D2: Alim, hygiène, sommeil, bouger, écrans | E2: =COUNTIF('22-Leçons'!A:A,A2) -> 9 | F2: =COUNTIFS('22-Leçons'!A:A,A2,'22-Leçons'!I:I,"V1-pilote") -> 1 | G2: Maison, repas, soir
A3: SEC | B3: Sécurité | C3: Où mettre le corps, qui appeler. | D3: Rue, maison, parc, adulte | E3: =COUNTIF('22-Leçons'!A:A,A3) -> 9 | F3: =COUNTIFS('22-Leçons'!A:A,A3,'22-Leçons'!I:I,"V1-pilote") -> 3 | G3: Rue, maison, magasin, parc
A4: EMO | B4: Émotions | C4: Nommer et choisir un geste sûr. | D4: Lexique, geste | E4: =COUNTIF('22-Leçons'!A:A,A4) -> 12 | F4: =COUNTIFS('22-Leçons'!A:A,A4,'22-Leçons'!I:I,"V1-pilote") -> 2 | G4: Après un petit problème
A5: REL | B5: Relations | C5: Vivre avec les autres sans se faire mal. | D5: Partage, conflit, amitié, moqueries | E5: =COUNTIF('22-Leçons'!A:A,A5) -> 10 | F5: =COUNTIFS('22-Leçons'!A:A,A5,'22-Leçons'!I:I,"V1-pilote") -> 4 | G5: Parc, école, maison
A6: DIF | B6: Différences du quotidien | C6: Ne pas se moquer. Jouer avec. | D6: Corps, parole, énergie, besoins | E6: =COUNTIF('22-Leçons'!A:A,A6) -> 8 | F6: =COUNTIFS('22-Leçons'!A:A,A6,'22-Leçons'!I:I,"V1-pilote") -> 2 | G6: Parc, école
A7: AUT | B7: Autonomie | C7: S'occuper de ses affaires. | D7: Affaires, rangement, routines | E7: =COUNTIF('22-Leçons'!A:A,A7) -> 5 | F7: =COUNTIFS('22-Leçons'!A:A,A7,'22-Leçons'!I:I,"V1-pilote") -> 2 | G7: Départ, retour
A8: FAM | B8: Famille et confiance | C8: Parler à papa et maman. | D8: Vérité, surprise/secret, aide | E8: =COUNTIF('22-Leçons'!A:A,A8) -> 4 | F8: =COUNTIFS('22-Leçons'!A:A,A8,'22-Leçons'!I:I,"V1-pilote") -> 0 | G8: Maison
A9: COL | B9: Vie collective | C9: Mots et règles de la classe. | D9: Politesse, école | E9: =COUNTIF('22-Leçons'!A:A,A9) -> 3 | F9: =COUNTIFS('22-Leçons'!A:A,A9,'22-Leçons'!I:I,"V1-pilote") -> 0 | G9: École
A10: VIV | B10: Monde vivant | C10: Noms, cris, petits, soin. | D10: Animaux, plantes | E10: =COUNTIF('22-Leçons'!A:A,A10) -> 4 | F10: =COUNTIFS('22-Leçons'!A:A,A10,'22-Leçons'!I:I,"V1-pilote") -> 0 | G10: Ferme, jardin
A11: TMP | B11: Temps et nature | C11: Jour, semaine, année. | D11: Jour/nuit, semaine, mois, saisons, météo | E11: =COUNTIF('22-Leçons'!A:A,A11) -> 6 | F11: =COUNTIFS('22-Leçons'!A:A,A11,'22-Leçons'!I:I,"V1-pilote") -> 0 | G11: Fenêtre, manteau
A12: SOC | B12: Vie concrète | C12: Métiers, argent, transports, cuisine. | D12: Transports, métiers, argent, cuisine, lieux | E12: =COUNTIF('22-Leçons'!A:A,A12) -> 7 | F12: =COUNTIFS('22-Leçons'!A:A,A12,'22-Leçons'!I:I,"V1-pilote") -> 0 | G12: Gare, marché, cuisine
A13: JEU | B13: Jeux et sport | C13: Jouer ensemble, accepter le résultat. | D13: Ballon, foot, basket, règles | E13: =COUNTIF('22-Leçons'!A:A,A13) -> 5 | F13: =COUNTIFS('22-Leçons'!A:A,A13,'22-Leçons'!I:I,"V1-pilote") -> 0 | G13: Parc, récré
A14: LAN | B14: Langage et logique | C14: Nommer, classer, compter. | D14: Mots, nombres, sons | E14: =COUNTIF('22-Leçons'!A:A,A14) -> 3 | F14: =COUNTIFS('22-Leçons'!A:A,A14,'22-Leçons'!I:I,"V1-pilote") -> 0 | G14: Cuisine, trajet

Sheet 21-Sous-domaines
A1: ID | B1: Domaine | C1: Sous-domaine | D1: Nb leçons
A2: SAN.ALI | B2: Santé et quotidien | C2: Alimentation | D2: =COUNTIF('22-Leçons'!C:C,A2) -> 3
A3: SAN.HYG | B3: Santé et quotidien | C3: Hygiène | D3: =COUNTIF('22-Leçons'!C:C,A3) -> 3
A4: SAN.SOM | B4: Santé et quotidien | C4: Sommeil | D4: =COUNTIF('22-Leçons'!C:C,A4) -> 1
A5: SAN.MOV | B5: Santé et quotidien | C5: Bouger | D5: =COUNTIF('22-Leçons'!C:C,A5) -> 1
A6: SAN.ECR | B6: Santé et quotidien | C6: Écrans | D6: =COUNTIF('22-Leçons'!C:C,A6) -> 1
A7: SEC.RUE | B7: Sécurité | C7: Rue et trajet | D7: =COUNTIF('22-Leçons'!C:C,A7) -> 3
A8: SEC.MAI | B8: Sécurité | C8: Maison | D8: =COUNTIF('22-Leçons'!C:C,A8) -> 3
A9: SEC.PAR | B9: Sécurité | C9: Parc et dehors | D9: =COUNTIF('22-Leçons'!C:C,A9) -> 1
A10: SEC.ADU | B10: Sécurité | C10: Aller vers un adulte | D10: =COUNTIF('22-Leçons'!C:C,A10) -> 2
A11: EMO.LEX | B11: Émotions | C11: Nommer l'émotion | D11: =COUNTIF('22-Leçons'!C:C,A11) -> 10
A12: EMO.GES | B12: Émotions | C12: Geste sûr | D12: =COUNTIF('22-Leçons'!C:C,A12) -> 2
A13: REL.PAR | B13: Relations | C13: Partage et tour | D13: =COUNTIF('22-Leçons'!C:C,A13) -> 2
... A45: LAN.SON | B45: Langage et logique | C45: Sons | D45: =COUNTIF('22-Leçons'!C:C,A45) -> 1

Sheet 22-Leçons
A1: Domaine ID | B1: Domaine | C1: Sous ID | D1: Sous-domaine | E1: Leçon ID | F1: Titre | G1: Objectif | H1: Framing | I1: Vague | J1: required_messages | K1: safe_actions | L1: misconceptions | M1: forbidden_in_audio | N1: answer_intents | O1: sensitivity
A2: SAN | B2: Santé et quotidien | C2: SAN.ALI | D2: Alimentation | E2: SAN.ALI.001 | F2: Goûter un légume | G2: Goûter une petite portion et nommer le goût, sans chantage. | H2: standard | I2: V1-pilote | J2: goûter;petite portion;nommer le goût | K2: prendre une petite bouchée;dire le goût à papa ou maman | L2: il faut tout finir;on force | M2: humiliation;chantage dessert | N2: GOUTER;PETITE_BOUCHEE | O2: standard
A3: SAN | B3: Santé et quotidien | C3: SAN.ALI | D3: Alimentation | E3: SAN.ALI.002 | F3: S'asseoir pour manger | G3: Manger assis à table avec la famille. | H3: standard | I3: V1 | J3: assis;table;ensemble | K3: s'asseoir;poser les fesses sur la chaise | L3: manger en courant est bien | M3: moquerie de l'appétit | N3: ASSISE;TABLE | O3: standard
A4: SAN | B4: Santé et quotidien | C4: SAN.ALI | D4: Alimentation | E4: SAN.ALI.003 | F4: Boire de l'eau | G4: Quand on a soif, on boit de l'eau dans un verre. | H4: standard | I4: V1.1 | J4: eau;verre;soif | K4: prendre le verre d'eau | L4: toute boisson convient | N4: EAU;VERRE | O4: standard
A5: SAN | B5: Santé et quotidien | C5: SAN.HYG | D5: Hygiène | E5: SAN.HYG.001 | F5: Se laver les mains | G5: Avant de manger et après les toilettes, savon et eau. | H5: standard | I5: V1 | J5: savon;avant de manger;après les toilettes | K5: ouvrir l'eau;savon;rincer;essuyer | L5: eau seule suffit toujours | N5: SAVON;MAINS | O5: standard
A6: SAN | B6: Santé et quotidien | C6: SAN.HYG | D6: Hygiène | E6: SAN.HYG.002 | F6: Se brosser les dents | G6: Matin et soir avec papa ou maman. | H6: standard | I6: V1 | J6: matin;soir;brosse;adulte | K6: prendre la brosse;brosser avec l'adulte | L6: une fois par semaine suffit | N6: BROSSE;MATIN_SOIR | O6: standard
A7: SAN | B7: Santé et quotidien | C7: SAN.HYG | D7: Hygiène | E7: SAN.HYG.003 | F7: Se moucher | G7: Mouchoir puis poubelle. | H7: standard | I7: V1.1 | J7: mouchoir;poubelle | K7: prendre un mouchoir;jeter | N7: MOUCHOIR | O7: standard
A8: SAN | B8: Santé et quotidien | C8: SAN.SOM | D8: Sommeil | E8: SAN.SOM.001 | F8: Aller se coucher | G8: Pyjama, histoire, dodo. Le corps a besoin de dormir. | H8: standard | I8: V1 | J8: soir;pyjama;dodo | K8: mettre le pyjama;se coucher | L8: dormir est une punition | N8: PYJAMA;LIT | O8: standard
A9: SAN | B9: Santé et quotidien | C9: SAN.MOV | D9: Bouger | E9: SAN.MOV.001 | F9: Jouer dehors un moment | G9: Bouger au parc ou au jardin avec un adulte. | H9: standard | I9: V1.1 | J9: dehors;avec un adulte | K9: aller au parc avec papa ou maman | N9: DEHORS;AVEC_ADULTE | O9: standard
A10: SAN | B10: Santé et quotidien | C10: SAN.ECR | D10: Écrans | E10: SAN.ECR.001 | F10: Arrêter l'écran quand on dit stop | G10: Papa ou maman dit fini : on éteint, on prend un autre jeu. | H10: standard | I10: V1 | J10: éteindre;autre jeu;adulte dit fini | K10: éteindre;choisir un jeu | L10: on négocie sans fin | M10: menace affective | N10: ETEINDRE;AUTRE_JEU | O10: standard
A11: SEC | B11: Sécurité | C11: SEC.RUE | D11: Rue et trajet | E11: SEC.RUE.001 | F11: S'arrêter au bord du trottoir | G11: On s'arrête avant la chaussée. Pieds sur le trottoir. | H11: positive_only_critical | I11: V1-pilote | J11: trottoir;s'arrêter;pieds au bord | K11: s'arrêter;pieds sur le trottoir;attendre l'adulte | L11: on avance dès qu'on voit le passage | M11: décrire une course sur la chaussée | N11: TROTTOIR;ARRETER | O11: enhanced
A12: SEC | B12: Sécurité | C12: SEC.RUE | D12: Rue et trajet | E12: SEC.RUE.002 | F12: Attendre le feu vert avec l'adulte | G12: Feu vert piéton, main, on traverse avec l'adulte. | H12: positive_only_critical | I12: V1-pilote | J12: feu vert;main;adulte;trottoir en attendant | K12: attendre le feu vert;donner la main;avancer avec l'adulte | L12: un bruit suffit;l'enfant décide seul | M12: proposer d'avancer au rouge comme option | N12: FEU_VERT;MAIN;AVEC_ADULTE | O12: enhanced
A13: SEC | B13: Sécurité | C13: SEC.RUE | D13: Rue et trajet | E13: SEC.RUE.003 | F13: Rester près de l'adulte dans la rue | G13: On marche près de papa ou maman, main ou manteau. | H13: positive_only_critical | I13: V1 | J13: près de l'adulte;main ou manteau | K13: tenir la main;marcher à côté | L13: devant tout seul est plus grand | N13: PRES_ADULTE;MAIN | O13: enhanced
A14: SEC | B14: Sécurité | C14: SEC.MAI | D14: Maison | E14: SEC.MAI.001 | F14: Les prises sont pour les adultes | G14: Lumière ou prise : on appelle un adulte. Mains avec les jouets. | H14: positive_only_critical | I14: V1 | J14: appeler un adulte;mains avec les jouets | K14: appeler papa ou maman;garder les mains avec les jouets | M14: décrire un objet dans une prise | N14: APPELER_ADULTE;MAINS_JOUETS | O14: enhanced
A15: SEC | B15: Sécurité | C15: SEC.MAI | D15: Maison | E15: SEC.MAI.002 | F15: Demander avant de goûter l'inconnu | G15: Avant de toucher ou goûter ce qu'on ne connaît pas : papa ou maman. | H15: positive_only_critical | I15: V1 | J15: demander;inconnu;adulte | K15: demander à papa ou maman | M15: lister des produits dangereux | N15: DEMANDER;ADULTE | O15: enhanced
A16: SEC | B16: Sécurité | C16: SEC.MAI | D16: Maison | E16: SEC.MAI.003 | F16: Balcon : pieds au sol avec un adulte | G16: Derrière la protection, pieds au sol, avec un adulte. | H16: positive_only_critical | I16: V1 | J16: pieds au sol;protection;adulte | K16: rester derrière la protection;pieds au sol;avec un adulte | M16: décrire un saut ou une descente | N16: PIEDS_SOL;AVEC_ADULTE | O16: enhanced
A17: SEC | B17: Sécurité | C17: SEC.PAR | D17: Parc et dehors | E17: SEC.PAR.001 | F17: Jouer là où l'adulte peut voir | G17: On reste dans l'espace montré par papa ou maman. | H17: standard | I17: V1-pilote | J17: espace montré;adulte voit | K17: jouer là où l'adulte a dit | L17: plus loin tout seul | N17: ESPACE_MONTRE;ADULTE_VOIT | O17: standard
A18: SEC | B18: Sécurité | C18: SEC.ADU | D18: Aller vers un adulte | E18: SEC.ADU.001 | F18: Chercher papa, maman ou la maîtresse | G18: Peur ou perdu au magasin : on va vers papa, maman ou la maîtresse. | H18: positive_only_critical | I18: V1 | J18: papa;maman;maîtresse | K18: aller vers papa ou maman ou la maîtresse | L18: suivre n'importe qui qui sourit | M18: décrire un inconnu qui emmène | N18: PAPA_MAMAN;MAITRESSE | O18: enhanced
A19: SEC | B19: Sécurité | C19: SEC.ADU | D19: Aller vers un adulte | E19: SEC.ADU.002 | F19: Rester avec l'adulte connu | G19: On reste avec la personne de la famille ou de l'école qui nous accompagne. | H19: positive_only_critical | I19: V1 | J19: rester avec l'accompagnant | K19: rester à côté de l'adulte connu | N19: RESTER_AVEC | O19: enhanced
A20: EMO | B20: Émotions | C20: EMO.LEX | D20: Nommer l'émotion | E20: EMO.LEX.001 | F20: Être content | G20: Nommer la joie et la partager sans écraser l'autre. | H20: emotional | I20: V1 | J20: content;joie;partager | K20: dire je suis content;sourire;inviter | L20: être content = être meilleur | N20: CONTENT;JOIE | O20: standard
A21: EMO | B21: Émotions | C21: EMO.LEX | D21: Nommer l'émotion | E21: EMO.LEX.002 | F21: Être triste | G21: Pleurer est permis. On peut demander un câlin. | H21: emotional | I21: V1 | J21: triste;pleurer permis;câlin | K21: dire je suis triste;demander un câlin | L21: les grands ne pleurent pas | M21: humiliation des larmes | N21: TRISTE;CALIN | O21: standard
A22: EMO | B22: Émotions | C22: EMO.LEX | D22: Nommer l'émotion | E22: EMO.LEX.003 | F22: Être déçu | G22: Un souhait peut attendre. On nomme et on cherche une autre idée. | H22: emotional | I22: V1 | J22: déçu;autre idée | K22: dire je suis déçu;proposer autre chose | L22: colère obligatoire | N22: DECU;AUTRE_IDEE | O22: standard
A23: EMO | B23: Émotions | C23: EMO.LEX | D23: Nommer l'émotion | E23: EMO.LEX.004 | F23: Être surpris | G23: On respire et on comprend avant d'agir. | H23: emotional | I23: V1.1 | J23: surpris;respirer;comprendre | K23: souffler;regarder | N23: SURPRIS;SOUFFLER | O23: standard
A24: EMO | B24: Émotions | C24: EMO.LEX | D24: Nommer l'émotion | E24: EMO.LEX.005 | F24: Être en colère | G24: On nomme. Mains loin de l'autre. On s'éloigne, on souffle, on va vers un adulte. | H24: emotional | I24: V1-pilote | J24: colère;mains loin;s'éloigner;adulte | K24: dire je suis en colère;s'éloigner;souffler;aller vers un adulte | L24: frapper est normal si on est en colère | M24: mode d'emploi pour frapper | N24: COLERE;ELOIGNER;ADULTE | O24: standard
A25: EMO | B25: Émotions | C25: EMO.LEX | D25: Nommer l'émotion | E25: EMO.LEX.006 | F25: Être inquiet | G25: Ventre serré : on rejoint un adulte et on raconte. | H25: emotional | I25: V1 | J25: inquiet;adulte;raconter | K25: aller vers papa ou maman;raconter | N25: INQUIET;RACONTER | O25: standard
A26: EMO | B26: Émotions | C26: EMO.LEX | D26: Nommer l'émotion | E26: EMO.LEX.007 | F26: Être nerveux | G26: Le corps n'arrive pas à tenir : on demande une pause. | H26: emotional | I26: V1.1 | J26: nerveux;pause | K26: demander une pause;s'asseoir | L26: nerveux = vilain | M26: étiquette hyperactif comme insulte | N26: NERVEUX;PAUSE | O26: standard
A27: EMO | B27: Émotions | C27: EMO.LEX | D27: Nommer l'émotion | E27: EMO.LEX.008 | F27: Être gêné | G27: Une erreur ne définit pas l'enfant. On dit et on répare. | H27: emotional | I27: V1.1 | J27: gêné;erreur;réparer | K27: dire;réparer | L27: honte comme identité | N27: GENE;REPARER | O27: standard
A28: EMO | B28: Émotions | C28: EMO.LEX | D28: Nommer l'émotion | E28: EMO.LEX.009 | F28: Être jaloux | G28: On nomme l'envie. On demande un tour. On ne prend pas de force. | H28: emotional | I28: V1 | J28: jaloux;demander un tour | K28: dire;attendre;demander | L28: prendre le jouet règle l'envie | N28: JALOUX;TOUR | O28: standard
A29: EMO | B29: Émotions | C29: EMO.LEX | D29: Nommer l'émotion | E29: EMO.LEX.010 | F29: Être fier | G29: Content d'un effort, sans rabaisser l'autre. | H29: emotional | I29: V1.1 | J29: fier;effort | K29: dire je suis fier de mon effort | L29: fier = supérieur | N29: FIER;EFFORT | O29: standard
A30: EMO | B30: Émotions | C30: EMO.GES | D30: Geste sûr | E30: EMO.GES.001 | F30: Dire stop et s'éloigner | G30: Quand c'est trop : stop, distance, adulte. | H30: emotional | I30: V1-pilote | J30: stop;s'éloigner;adulte | K30: dire stop;s'éloigner;aller vers un adulte | L30: rester et encaisser | N30: STOP;ELOIGNER;ADULTE | O30: standard
A31: EMO | B31: Émotions | C31: EMO.GES | D31: Geste sûr | E31: EMO.GES.002 | F31: Respirer et faire une pause | G31: Souffler, s'asseoir, reprendre. | H31: emotional | I31: V1 | J31: souffler;pause | K31: souffler;s'asseoir | N31: SOUFFLER;PAUSE | O31: standard
A32: REL | B32: Relations | C32: REL.PAR | D32: Partage et tour | E32: REL.PAR.001 | F32: Partager un jouet | G32: Prêter, attendre son tour, ou proposer un autre jeu. | H32: standard | I32: V1-pilote | J32: prêter;tour;autre jeu | K32: prêter;attendre;proposer un autre jeu | L32: garder tout est gagner | N32: PRETER;TOUR;AUTRE_JEU | O32: standard
A33: REL | B33: Relations | C33: REL.PAR | D33: Partage et tour | E33: REL.PAR.002 | F33: Attendre son tour | G33: L'autre finit, puis c'est notre tour. | H33: standard | I33: V1 | J33: attendre;puis mon tour | K33: attendre;puis jouer | N33: ATTENDRE;TOUR | O33: standard
A34: REL | B34: Relations | C34: REL.CON | D34: Conflit | E34: REL.CON.001 | F34: Un camarade bouscule au parc | G34: Stop, s'éloigner, aller vers papa ou maman au banc. | H34: standard | I34: V1-pilote | J34: stop;s'éloigner;parent au parc | K34: dire stop;s'éloigner;aller vers papa ou maman | L34: rendre un coup d'abord | M34: décrire comment frapper | N34: STOP;ELOIGNER;PARENT | O34: standard
A35: REL | B35: Relations | C35: REL.CON | D35: Conflit | E35: REL.CON.002 | F35: Un camarade bouscule à l'école | G35: Stop, s'éloigner, aller vers la maîtresse ou le maître. | H35: standard | I35: V1 | J35: stop;s'éloigner;maîtresse | K35: dire stop;s'éloigner;aller vers la maîtresse | L35: se cacher et ne rien dire | M35: bagarre comme jeu | N35: STOP;ELOIGNER;MAITRESSE | O35: standard
A36: REL | B36: Relations | C36: REL.CON | D36: Conflit | E36: REL.CON.003 | F36: Réparer après une bêtise | G36: Pardon et un geste simple. Ça n'efface pas tout de suite la peine. | H36: standard | I36: V1 | J36: pardon;geste;peine reste un peu | K36: dire pardon;proposer un geste | L36: pardon magique efface tout | M36: forcer l'amitié | N36: PARDON;GESTE | O36: standard
A37: REL | B37: Relations | C37: REL.AMI | D37: Amitié | E37: REL.AMI.001 | F37: Inviter à jouer | G37: « Tu veux jouer avec nous ? » Un non est possible. | H37: standard | I37: V1 | J37: inviter;accepter un non | K37: demander;accepter le non | L37: insister jusqu'au oui | N37: INVITER;ACCEPTER_NON | O37: standard
A38: REL | B38: Relations | C38: REL.MOQ | D38: Moqueries | E38: REL.MOQ.001 | F38: Ne pas rire d'un camarade | G38: On ne se moque pas, on ne répète pas, on dit que ce n'est pas gentil. | H38: respect | I38: V1-pilote | J38: pas rire;pas répéter;pas gentil | K38: ne pas rire;dire ce n'est pas gentil | L38: rire = appartenir au groupe | M38: enseigner un surnom | N38: PAS_RIRE;PAS_GENTIL | O38: standard
A39: REL | B39: Relations | C39: REL.MOQ | D39: Moqueries | E39: REL.MOQ.002 | F39: Rejoindre celui qui est à l'écart | G39: On va vers lui, on l'invite, on prévient un adulte si ça continue. | H39: respect | I39: V1-pilote | J39: rejoindre;inviter;adulte si ça continue | K39: aller vers lui;inviter;prévenir un adulte | L39: toute la réparation sur le visé | N39: REJOINDRE;INVITER;ADULTE | O39: standard
A40: REL | B40: Relations | C40: REL.MOQ | D40: Moqueries | E40: REL.MOQ.003 | F40: Raconter à papa ou maman | G40: On raconte, même si on a soi-même ri. | H40: respect | I40: V1 | J40: raconter;même si on a ri | K40: raconter à papa ou maman | N40: RACONTER;PAPA_MAMAN | O40: standard
...

Sheet 23-Fiches-pilote
B2: Contrats exécutables — arbre Parc (à coller dans le validateur)
A4: Leçon ID | B4: Titre | C4: required_messages | D4: safe_actions | E4: question type | F4: question exemple | G4: intents OK | H4: correction si erreur | I4: ne jamais écrire dans l'audio
A5: SEC.RUE.001 | B5: S'arrêter au bord | C5: trottoir; s'arrêter; pieds | D5: s'arrêter; pieds sur le trottoir | E5: lesson | F5: Où sont les pieds quand on attend ? | G5: TROTTOIR; ARRETER | H5: Les pieds restent sur le trottoir, avec l'adulte. | I5: courir au milieu; traverser tout seul
A6: SEC.RUE.002 | B6: Feu vert + adulte | C6: feu vert; main; adulte; attendre | D6: attendre le feu vert; donner la main; avancer avec l'adulte | E6: lesson | F6: Quand le feu piéton est encore rouge, où attend-on ? | G6: TROTTOIR; AVEC_ADULTE; ATTENDRE | H6: On attend sur le trottoir, la main dans la main. | I6: avancer au rouge; l'enfant décide seul
A7: SEC.PAR.001 | B7: Là où l'adulte voit | C7: espace montré; adulte voit | D7: jouer dans l'espace montré | E7: comprehension | F7: Où est-ce qu'on joue ? | G7: ESPACE_MONTRE; PRES_ADULTE | H7: On joue là où papa ou maman peut voir. | I7: partir derrière le bâtiment
A8: REL.PAR.001 | B8: Partager le ballon | C8: prêter; tour; autre jeu | D8: prêter; attendre; proposer un autre jeu | E8: lesson | F8: Le ballon est pris. Que peut-on faire ? | G8: PRETER; TOUR; AUTRE_JEU | H8: On peut attendre son tour ou proposer un autre jeu. | I8: arracher; frapper pour reprendre
A9: REL.CON.001 | B9: Bousculade au parc | C9: stop; s'éloigner; parent | D9: dire stop; s'éloigner; aller vers papa ou maman | E9: lesson | F9: Un camarade a bousculé. Que fait-on ? | G9: STOP; ELOIGNER; PARENT | H9: On dit stop, on s'éloigne, on va vers papa ou maman. | I9: comment rendre un coup
A10: EMO.LEX.005 | B10: Colère | C10: colère; mains loin; s'éloigner | D10: nommer; s'éloigner; souffler; adulte | E10: lesson | F10: Le ventre est chaud, les poings serrés. Comment ça s'appelle ? | G10: COLERE | H10: C'est la colère. Les mains restent loin. On s'éloigne. | I10: frapper pour se calmer
A11: EMO.GES.001 | B11: Stop et s'éloigner | C11: stop; s'éloigner; adulte | D11: dire stop; marcher vers l'adulte | E11: lesson | F11: C'est trop. Que dit-on ? | G11: STOP; ELOIGNER | H11: On dit stop et on va vers l'adulte.
A12: DIF.COR.001 | B12: Plus petit / plus grand | C12: jouer ensemble; pas commenter pour rabaisser | D12: inviter au ballon | E12: lesson | F12: On peut jouer avec un camarade plus petit ? | G12: OUI; JOUER_ENSEMBLE | H12: Oui. On l'invite. Les tailles sont différentes. | I12: surnom sur la taille
A13: DIF.ENE.001 | B13: Beaucoup d'énergie | C13: énergie pas une faute; jouer ou attendre | D13: jouer; attendre son tour; demander à l'adulte | E13: lesson | F13: Il bouge beaucoup. Que peut-on faire ? | G13: JOUER; ATTENDRE; ADULTE | H13: On peut jouer avec lui ou attendre. Ce n'est pas une faute. | I13: hyperactif comme insulte
A14: REL.MOQ.001 | B14: Ne pas rire | C14: pas rire; pas répéter; pas gentil | D14: ne pas rire; dire ce n'est pas gentil | E14: lesson | F14: On entend une moquerie. Que fait-on ? | G14: PAS_RIRE; PAS_GENTIL | H14: On ne rit pas. On dit que ce n'est pas gentil. | I14: répéter le surnom
A15: REL.MOQ.002 | B15: Rejoindre | C15: rejoindre; inviter; adulte si ça continue | D15: aller vers lui; inviter; prévenir un adulte | E15: lesson | F15: Un camarade est tout seul après une moquerie. Que fait-on ? | G15: REJOINDRE; INVITER | H15: On va vers lui et on l'invite. Si ça continue, on prévient un adulte. | I15: toute la charge sur le visé
A16: AUT.AFF.003 | B16: Affaires avant de partir | C16: reprendre; avant de partir | D16: chercher seau et manteau; les prendre | E16: lesson | F16: Avant de rentrer, que reprend-on ? | G16: MANTEAU; SEAU; AFFAIRES | H16: On reprend ses affaires : manteau, seau, doudou.

Sheet 24-Arbre-Parc
B2: Arbre pilote TREE-PARC-001 — plusieurs fins distinctes
A4: Scène | B4: Leçon | C4: Rôle | D4: Type nœud | E4: Consignes génération
A5: Trajet — bord du trottoir | B5: SEC.RUE.001 | C5: principale | D5: audio + question_lesson | E5: Pieds sur le trottoir. Ne pas raconter une course sur la chaussée.
A6: Traversée | B6: SEC.RUE.002 | C6: principale | D6: audio + question_lesson | E6: Feu vert, main, adulte. Question : où attend-on ? Options toutes positives.
A7: Arrivée | B7: SEC.PAR.001 | C7: secondaire | D7: audio | E7: Espace que papa ou maman a montré.
A8: Choix lieu | B8: — | C8: narratif | D8: choice_story | E8: Bac à sable ou ballon. Aucune option morale.
A9: Ballon | B9: REL.PAR.001 | C9: principale de scène | D9: audio + question_lesson | E9: Prêter / tour / autre jeu.
A10: Bousculade | B10: REL.CON.001 | C10: principale de scène | D10: audio + question_lesson | E10: Stop, loin, parent. Pas de mode d'emploi de bagarre.
A11: Colère | B11: EMO.LEX.005 | C11: liée | D11: audio + question_lesson | E11: Nommer. Mains loin.
A12: Geste | B12: EMO.GES.001 | C12: renfort | D12: feedback | E12: Stop et s'éloigner — réutilise la scène.
A13: Branche A taille | B13: DIF.COR.001 | C13: branche | D13: audio + question | E13: Inviter. Pas de commentaire rabaissant.
A14: Branche B énergie | B14: DIF.ENE.001 | C14: branche | D14: audio + question | E14: Jouer ou attendre. Pas d'étiquette.
A15: Branche C moquerie | B15: REL.MOQ.001 + 002 | C15: branche | D15: audio + question + feedback | E15: Ne pas rire. Rejoindre. Adulte si ça continue. Pas de surnom répété.
A16: Départ | B16: AUT.AFF.003 | C16: fermeture | D16: audio + question + ending | E16: Manteau, seau. Trois fins possibles selon la branche : rentrer calme / rentrer après avoir parlé / rentrer avec un nouvel ami de jeu.

Sheet 30-Strategie-validation
B2: Stratégie de validation
B3: Le moteur vit en production éditoriale. L'app d'écoute n'exécute que des paquets APPROVED_PACKAGE.
B5: Pipeline (un arbre)
B6: 1. Contrat pédagogique versionné (onglet 23 pour le parc, onglet 22 pour le reste).
B7: 2. Génération hors validateur (F-GEN-001).
B8: 3. Compilateur graphe + énumération 100 % des chemins.
B9: 4. Règles déterministes : hors-jardin, étiquettes, imitabilité, âge, questions, droit.
B10: 5. Sémantique + adversaire sur chaque chemin (leçon retenue, contradiction, qui est récompensé).
B11: 6. Orchestrateur → REJECTED / REVISION / HUMAN_REVIEW / APPROVED_TEXT.
B12: 7. Revue humaine si matrice ou désaccord ou sensibilité enhanced/specialist.
B13: 8. TTS seulement si APPROVED_TEXT. Texte ensuite figé.
B14: 9. ASR vs texte + acoustique + durées réelles.
... B39: Changement de règle → retest ciblé. Risque critique découvert → retrait des paquets déjà téléchargés (VAL-TRACE-002 + F-ADM-002).

Sheet 31-Backlog-validation
A1: ID | B1: Couche | C1: Titre | D1: Description | E1: Priorité | F1: Phase VAL | G1: Statut
A2: VAL-001 | B2: Gouvernance | C2: Le générateur ne s'auto-approuve pas | D2: Publication = preuves signées d'un autre service. | E2: P0 | F2: VAL-5 | G2: À faire
A3: VAL-002 | B3: Gouvernance | C3: Une violation bloquante tue l'arbre | D3: Un seul chemin défaillant suffit. Pas de moyenne miracle. | E3: P0 | F3: VAL-5 | G3: À faire
A4: VAL-003 | B4: Gouvernance | C4: Décisions reproductibles | D4: Règle, version, span, modèle, paramètres. On rejoue le contrôle. | E4: P0 | F4: VAL-5 | G4: À faire
A5: VAL-DEC-001 | B5: Gouvernance | C5: États d'orchestrateur | D5: REJECTED / REVISION_REQUIRED / HUMAN_REVIEW_REQUIRED / APPROVED_TEXT / APPROVED_PACKAGE. | E5: P0 | F5: VAL-5 | G5: À faire
A6: VAL-DEC-002 | B6: Gouvernance | C6: Gravités | D6: BLOQUANT rejet. MAJEUR révision ou humain. MINEUR reco. INFO journal. | E6: P0 | F6: VAL-5 | G6: À faire
A7: VAL-PED-001 | B7: Contrat | C7: Fiche avant génération | D7: Pas d'arbre sans contrat versionné. | E7: P0 | F7: VAL-1 | G7: À faire
A8: VAL-PED-002 | B8: Contrat | C8: Messages essentiels par chemin | D8: required_messages présents, misconceptions absentes. | E8: P0 | F8: VAL-4 | G8: À faire
A9: VAL-PED-010 | B9: Preuve | C9: Six preuves minimales | D9: Situation, enjeu, modèle sûr, mobilisation, confirmation, conséquence non inverse. | E9: P0 | F9: VAL-4 | G9: À faire
A10: VAL-PED-011 | B10: Preuve | C10: Leçon réellement retenue | D10: Le validateur dit ce qu'un enfant retiendrait, puis compare. | E10: P1 | F10: VAL-4 | G10: À faire
A11: VAL-PED-012 | B11: Preuve | C11: Scores non moyennables | D11: ALIGN COVER ACCURACY ACTION CLARITY COHERENCE CONTRADICTION. COVER/ACCURACY/CONTRADICTION bloquants si fail. | E11: P1 | F11: VAL-4 | G11: À faire
A12: VAL-NEU-001 | B12: Neutralité | C12: Contexte, pas liste seule | D12: Rôle du mot. Narrateur / héros / opposant / correction séparés. | E12: P0 | F12: VAL-3 | G12: À faire
... A37: VAL-TRACE-002 | B37: Exploitation | C37: Retest et retrait | D37: Règle nouvelle → retest ciblé. Risque critique → purge des paquets déjà DL. | E37: P2 | F37: VAL-5 | G37: À faire

Sheet 32-Revue-humaine
A1: Sujet | B1: Revue minimale | C1: Exemples de leçons
A2: Sécurité physique / circulation | B2: Éditoriale renforcée + spécialiste selon catégorie | C2: SEC.RUE.* SEC.MAI.* SOC.TRA.002
A3: Conflit entre enfants | B3: Éditoriale | C3: REL.CON.* EMO.LEX.005
A4: Moqueries / corps / énergie | B4: Relecteur formé aux différences du quotidien | C4: REL.MOQ.* DIF.*
A5: Secrets, malaise, protection | B5: Protection de l'enfance | C5: FAM.SEC.002 COL.ECO.001
A6: Santé clinique / médicaments | B6: Professionnel compétent — hors catalogue V1 sauf demande | C6: aucune leçon V1
A7: Trouble nommé (TDAH, etc.) | B7: Spécialiste — sinon on décrit le besoin sans étiquette | C7: DIF.ENE.001 reste descriptif
A8: Leçon saisie par un parent | B8: Qualification avant toute génération enfant | C8: F-CUS-*
A9: Droit / franchise | B9: Juridique si doute | C9: F-DRT-001

Sheet 40-Contrats
B2: Contrats de données — F-SCH-001
A4: Objet | B4: Champs minimum | C4: Notes
A5: lesson | B5: lesson_id, version, title, age_band, objective, required_messages[], safe_actions[], misconceptions[], forbidden_messages[], answer_intents[], framing, sensitivity, compatible_lessons[], banned_child_audio[] | C5: ID = SEC.RUE.002
A6: node | B6: node_id, type, audio_ref, text_approved, lesson_ids[], next[], default_next, intents[] | C6: type enum du moteur
A7: intent | B7: intent_id, examples[], forbidden_phrases[], negation_policy, on_match, on_wrong, on_ambiguous, on_silence | C7: négation avant similarité
A8: tree | B8: tree_id, version, age_band, duration_min_ms, duration_avg_ms, duration_max_ms, root_id, lessons_primary[], lessons_secondary[], endings[] | C8: durées = audio réel
A9: validation_report | B9: tree_id, tree_version, lesson_contracts[], paths_theoretical, paths_tested, paths_approved, blocking_findings[], scores{}, ruleset_version, final_status | C9: final_status enum orchestrateur
A10: package_manifest | B10: tree_id, tree_version, files[{path, sha256, duration_ms}], report_id, status=APPROVED_PACKAGE | C10: activation atomique
A11: enum node.type | B11: audio | question_comprehension | question_lesson | choice_story | feedback | transition | silence_check | ending
A12: enum local_state | B12: AVAILABLE | IN_PROGRESS | CONSUMED | REPLAYABLE | EVICTION_CANDIDATE | REMOVED | EXCLUDED | DOWNLOAD_PENDING
A13: enum val_status | B13: REJECTED | REVISION_REQUIRED | HUMAN_REVIEW_REQUIRED | APPROVED_TEXT | APPROVED_PACKAGE
A14: enum voice_result | B14: MATCH | WRONG_EDUCATIONAL | AMBIGUOUS | NO_ANSWER | TECHNICAL_ERROR
A15: enum framing | B15: positive_only_critical | standard | emotional | respect
A16: enum sensitivity | B16: standard | enhanced | specialist
A17: enum vague | B17: V1-pilote | V1 | V1.1 | Plus tard
